Workbook

Sheet README
A1: Construction Contractor L4-L5-L6 Schedule (Synthetic Case)
A3: Purpose | B3: Teaching dataset for the hackathon: shows how executor-level work (L5/L6 tasks reported by supervisors) hangs under the planner's L3/L4 nodes in Primavera P6, and gives a common ground truth to test extraction and schedule-linking.
A4: Case project | B4: Urban garbage treatment plant (100 TPD: segregation, composting, RDF), Town XYZ, by Company ABC. About Rs 45 crore, about 24 months from investment approval to commissioning. This workbook covers only the scope of the construction contractor.
A5: Sheets | B5: Assumptions: handover date and external delivery dates (scenario levers). L3 Reference: the 11 L3 activities given to the contractor. L4-L6 Schedule: the working schedule with logic, dates and actuals columns.
A6: Level definitions | B6: L3 = package activity in the consultant schedule (e.g. Civil Works - Process Buildings). L4 = facility / area work package (e.g. Waste Receiving & Tipping Hall). L5 = work group (e.g. Foundations). L6 = executable task reported daily by a supervisor (e.g. Excavate for footings).
A7: Linkage key | B7: The Activity ID (format GWP-<discipline>-<number>, e.g. GWP-CIV-1130) is the linkage point. Every L4-L6 row also carries its L3 Parent ID and immediate Parent ID, so a reported L6 task always resolves up to its L3/L4 node in P6.
A8: Who does what | B8: Contractor keeps L5/L6 (approved by consultant). Supervisors report L6 starts and finishes. The planning engineer confirms and updates P6. L4/L5 rows are never reported directly; they roll up.
A9: Completion rule | B9: A task is complete when the site team finishes the work. Inspection and testing are separate tasks in the last L3 node (Section GWP-L3-110), not part of the work task.
A10: Rollup rules | B10: Summary Planned/Actual Start = earliest child. Summary Actual Finish appears only when all L6 tasks below it are finished, then = latest child finish. Summary % Complete = L6 % complete weighted by planned duration. Status derives from the actual dates.
A11: Schedule logic | B11: L6 tasks use Finish-to-Start unless stated (some Start-to-Start with lag). Start = latest predecessor constraint, moved to next working day. Six-day week (Sunday off). Changing a duration or an external delivery offset recalculates all dates.
A12: Legend | B12: Yellow cells: fill in during demo (Actual Start, Actual Finish, % Complete, Remarks at L6 level; and delivery offsets on the Assumptions sheet). Blue text: hardcoded input (duration, quantity). Black: formula. Green: link to another sheet. Use the outline buttons (1/2/3) at the left of the schedule to collapse to L4, L5 or L6.
A13: Assumptions | B13: All durations, quantities, delivery lead times and logic are synthetic assumptions made for teaching realism, not taken from any real OIL project. Quantities are indicative and are meant to make daily reports look realistic (e.g. "poured 45 m3").
A15: Example of a filled-in row | B15: GWP-CIV-1250 | Excavate for footings (Bldg B) | Actual Start 18-Nov-27 | Actual Finish 24-Nov-27 | % Complete 100%. Only L6 rows are filled; the parent L5 and L4 rows and the L3 node update by formula. Delete any test entries before reuse.
A17: Row counts (live)
A18: L4 work packages | B18: =COUNTIF('L4-L6 Schedule'!$C$6:$C$220,"L4") -> 19
A19: L5 work groups | B19: =COUNTIF('L4-L6 Schedule'!$C$6:$C$220,"L5") -> 40
A20: L6 tasks (incl. 2 milestones) | B20: =COUNTIF('L4-L6 Schedule'!$C$6:$C$220,"L6") -> 149
A21: External milestones | B21: =COUNTIF('L4-L6 Schedule'!$C$6:$C$220,"EXT") -> 7
A22: Total rows | B22: =SUM(B18:B21) -> 215

Sheet Assumptions
A1: Assumptions & Scenario Levers
A2: Blue = editable input. All dates in the Schedule recalculate from these cells.
A4: Item | B4: Value | C4: Basis
A5: Investment approval date (case project) | B5: 46388 | C5: Case project assumption agreed with Sandip: ~24 months approval to commissioning
A6: Site handover to construction contractor (start of scope) | B6: 46664 | C6: Assumption: ~9 months after approval for land, statutory clearances and design
A7: Commissioning target (case project) | B7: 47118 | C7: Assumption: 24 months from approval
A8: Working calendar | B8: Mon-Sat (Sunday off) | C8: Assumption: 6-day week, no public holidays or monsoon losses modelled
A11: External / interface milestones (not contractor tasks - they drive the contractor schedule)
A12: Milestone ID | B12: Description | C12: Offset (working days from handover) | D12: Delivery date (calculated)
A13: GWP-EXT-1010 | B13: IFC structural steel drawings released by consultant | C13: 20 | D13: =WORKDAY.INTL(Assumptions!$B$6,C13,11) -> 46687
A14: GWP-EXT-1020 | B14: Trommel screen, conveyors, feed hopper & weighbridge delivered at site (supplier) | C14: 145 | D14: =WORKDAY.INTL(Assumptions!$B$6,C14,11) -> 46833
A15: GWP-EXT-1030 | B15: Shredder & baling press delivered at site (supplier) | C15: 155 | D15: =WORKDAY.INTL(Assumptions!$B$6,C15,11) -> 46844
A16: GWP-EXT-1040 | B16: Aeration blowers, compost turner & finishing screen delivered at site (supplier) | C16: 150 | D16: =WORKDAY.INTL(Assumptions!$B$6,C16,11) -> 46839
A17: GWP-EXT-1050 | B17: ETP skid, leachate & fire water pumps delivered at site (supplier) | C17: 155 | D17: =WORKDAY.INTL(Assumptions!$B$6,C17,11) -> 46844
A18: GWP-EXT-1060 | B18: Transformer, HT/LT panels & DG set delivered at site (owner-supplied) | C18: 175 | D18: =WORKDAY.INTL(Assumptions!$B$6,C18,11) -> 46868
A19: GWP-EXT-1070 | B19: PLC/SCADA panels & field instruments delivered at site (supplier) | C19: 205 | D19: =WORKDAY.INTL(Assumptions!$B$6,C19,11) -> 46903
A21: Notes:
A22: 1. Offsets are illustrative assumptions (supplier/owner lead times after design and ordering). Change an offset to test how a late delivery pushes the contractor schedule.
A23: 2. Task durations, quantities and logic in the Schedule are synthetic, chosen for teaching realism; they are not from any real OIL project.
A24: 3. No holidays, monsoon or weather losses are modelled. Dates use WORKDAY.INTL with Sunday as the only non-working day.

Sheet L4-L6 Schedule
A1: Level 4-5-6 Schedule: Construction Contractor Scope - Urban Garbage Treatment Plant (100 TPD), Town XYZ, Company ABC
A2: Synthetic teaching dataset. Link key = Activity ID (Primavera P6 style). Yellow cells = site inputs (Actual Start / Actual Finish / % Complete) at L6 task level; L4/L5 rows roll up automatically. Blue = editable input, black = formula.
A5: Activity ID | B5: WBS | C5: Level | D5: L3 Parent ID | E5: Parent ID | F5: Activity Name | G5: Type | H5: Discipline | I5: Reporting Role | J5: Qty | K5: UoM | L5: Orig Duration (wd) | M5: Predecessors (FS unless stated) | N5: Planned Start | O5: Planned Finish | P5: Leaf (Y/N) | Q5: Actual Start | R5: Actual Finish | S5: % Complete | T5: Status | U5: Remarks
A6: GWP-EXT-1010 | B6: - | C6: EXT | D6: - | E6: - | F6: IFC structural steel drawings released by consultant | G6: External milestone | H6: EXT | I6: Supplier / Owner / Consultant | L6: 0 | M6: Input date (Assumptions sheet) | N6: =Assumptions!$D$13 -> 46687 | O6: =N6 -> 46687 | P6: N | T6: -
A7: GWP-EXT-1020 | B7: - | C7: EXT | D7: - | E7: - | F7: Trommel screen, conveyors, feed hopper & weighbridge delivered at site (supplier) | G7: External milestone | H7: EXT | I7: Supplier / Owner / Consultant | L7: 0 | M7: Input date (Assumptions sheet) | N7: =Assumptions!$D$14 -> 46833 | O7: =N7 -> 46833 | P7: N | T7: -
A8: GWP-EXT-1030 | B8: - | C8: EXT | D8: - | E8: - | F8: Shredder & baling press delivered at site (supplier) | G8: External milestone | H8: EXT | I8: Supplier / Owner / Consultant | L8: 0 | M8: Input date (Assumptions sheet) | N8: =Assumptions!$D$15 -> 46844 | O8: =N8 -> 46844 | P8: N | T8: -
A9: GWP-EXT-1040 | B9: - | C9: EXT | D9: - | E9: - | F9: Aeration blowers, compost turner & finishing screen delivered at site (supplier) | G9: External milestone | H9: EXT | I9: Supplier / Owner / Consultant | L9: 0 | M9: Input date (Assumptions sheet) | N9: =Assumptions!$D$16 -> 46839 | O9: =N9 -> 46839 | P9: N | T9: -
A10: GWP-EXT-1050 | B10: - | C10: EXT | D10: - | E10: - | F10: ETP skid, leachate & fire water pumps delivered at site (supplier) | G10: External milestone | H10: EXT | I10: Supplier / Owner / Consultant | L10: 0 | M10: Input date (Assumptions sheet) | N10: =Assumptions!$D$17 -> 46844 | O10: =N10 -> 46844 | P10: N | T10: -
A11: GWP-EXT-1060 | B11: - | C11: EXT | D11: - | E11: - | F11: Transformer, HT/LT panels & DG set delivered at site (owner-supplied) | G11: External milestone | H11: EXT | I11: Supplier / Owner / Consultant | L11: 0 | M11: Input date (Assumptions sheet) | N11: =Assumptions!$D$18 -> 46868 | O11: =N11 -> 46868 | P11: N | T11: -
A12: GWP-EXT-1070 | B12: - | C12: EXT | D12: - | E12: - | F12: PLC/SCADA panels & field instruments delivered at site (supplier) | G12: External milestone | H12: EXT | I12: Supplier / Owner / Consultant | L12: 0 | M12: Input date (Assumptions sheet) | N12: =Assumptions!$D$19 -> 46903 | O12: =N12 -> 46903 | P12: N | T12: -
A13: GWP-GEN-1010 | B13: GWP.C01.01 | C13: L4 | D13: GWP-L3-010 | E13: GWP-L3-010 | F13: Mobilisation & Temporary Facilities | G13: Summary | H13: GEN | I13: Contractor Site Engineer | L13: =NETWORKDAYS.INTL(N13,O13,11) -> 14 | N13: =MIN(N14:N25) -> 46664 | O13: =MAX(O14:O25) -> 46679 | P13: N | Q13: =IF(COUNT(Q14:Q25)=0,"",MIN(Q14:Q25)) | R13: =IF(COUNTIFS(P14:P25,"Y")=COUNTIFS(P14:P25,"Y",R14:R25,">0"),MAX(R14:R25),"") | S13: =IFERROR(SUMPRODUCT((P14:P25="Y")*L14:L25*S14:S25)/SUMIFS(L14:L25,P14:P25,"Y"),0) -> 0 | T13: =IF(ISNUMBER(R13),"Completed",IF(ISNUMBER(Q13),"In Progress","Not Started")) -> Not Started
A14: GWP-GEN-1020 | B14: GWP.C01.01.01 | C14: L5 | D14: GWP-L3-010 | E14: GWP-GEN-1010 | F14: Site Establishment | G14: Summary | H14: GEN | I14: Contractor Site Engineer | L14: =NETWORKDAYS.INTL(N14,O14,11) -> 14 | N14: =MIN(N15:N20) -> 46664 | O14: =MAX(O15:O20) -> 46679 | P14: N | Q14: =IF(COUNT(Q15:Q20)=0,"",MIN(Q15:Q20)) | R14: =IF(COUNTIFS(P15:P20,"Y")=COUNTIFS(P15:P20,"Y",R15:R20,">0"),MAX(R15:R20),"") | S14: =IFERROR(SUMPRODUCT((P15:P20="Y")*L15:L20*S15:S20)/SUMIFS(L15:L20,P15:P20,"Y"),0) -> 0 | T14: =IF(ISNUMBER(R14),"Completed",IF(ISNUMBER(Q14),"In Progress","Not Started")) -> Not Started
A15: GWP-GEN-1030 | B15: GWP.C01.01.01.01 | C15: L6 | D15: GWP-L3-010 | E15: GWP-GEN-1020 | F15: Site handover & joint survey with consultant | G15: Task | H15: GEN | I15: Contractor Site Engineer | J15: 1 | K15: LS | L15: 2 | M15: Site handover date (Assumptions) | N15: =Assumptions!$B$6 -> 46664 | O15: =IF(L15=0,N15,WORKDAY.INTL(N15,L15-1,11)) -> 46665 | P15: Y | T15: =IF(ISNUMBER(R15),"Completed",IF(ISNUMBER(Q15),"In Progress","Not Started")) -> Not Started
A16: GWP-GEN-1040 | B16: GWP.C01.01.01.02 | C16: L6 | D16: GWP-L3-010 | E16: GWP-GEN-1020 | F16: Set up site office, stores & storage yard | G16: Task | H16: GEN | I16: Contractor Site Engineer | J16: 1 | K16: LS | L16: 6 | M16: GWP-GEN-1030 FS | N16: =IF($L16=0,O15,WORKDAY.INTL(O15,1,11)) -> 46666 | O16: =IF(L16=0,N16,WORKDAY.INTL(N16,L16-1,11)) -> 46672 | P16: Y | T16: =IF(ISNUMBER(R16),"Completed",IF(ISNUMBER(Q16),"In Progress","Not Started")) -> Not Started
A17: GWP-GEN-1050 | B17: GWP.C01.01.01.03 | C17: L6 | D17: GWP-L3-010 | E17: GWP-GEN-1020 | F17: Set up labour camp, canteen & sanitation | G17: Task | H17: GEN | I17: Contractor Site Engineer | J17: 1 | K17: LS | L17: 8 | M17: GWP-GEN-1030 FS | N17: =IF($L17=0,O15,WORKDAY.INTL(O15,1,11)) -> 46666 | O17: =IF(L17=0,N17,WORKDAY.INTL(N17,L17-1,11)) -> 46674 | P17: Y | T17: =IF(ISNUMBER(R17),"Completed",IF(ISNUMBER(Q17),"In Progress","Not Started")) -> Not Started
A18: GWP-GEN-1060 | B18: GWP.C01.01.01.04 | C18: L6 | D18: GWP-L3-010 | E18: GWP-GEN-1020 | F18: Arrange temporary power (DG) & water supply | G18: Task | H18: GEN | I18: Contractor Site Engineer | J18: 1 | K18: LS | L18: 7 | M18: GWP-GEN-1030 FS | N18: =IF($L18=0,O15,WORKDAY.INTL(O15,1,11)) -> 46666 | O18: =IF(L18=0,N18,WORKDAY.INTL(N18,L18-1,11)) -> 46673 | P18: Y | T18: =IF(ISNUMBER(R18),"Completed",IF(ISNUMBER(Q18),"In Progress","Not Started")) -> Not Started
A19: GWP-GEN-1070 | B19: GWP.C01.01.01.05 | C19: L6 | D19: GWP-L3-010 | E19: GWP-GEN-1020 | F19: Erect temporary fencing, signage & site gate | G19: Task | H19: GEN | I19: Contractor Site Engineer | J19: 300 | K19: RM | L19: 4 | M19: GWP-GEN-1030 FS | N19: =IF($L19=0,O15,WORKDAY.INTL(O15,1,11)) -> 46666 | O19: =IF(L19=0,N19,WORKDAY.INTL(N19,L19-1,11)) -> 46669 | P19: Y | T19: =IF(ISNUMBER(R19),"Completed",IF(ISNUMBER(Q19),"In Progress","Not Started")) -> Not Started
A20: GWP-GEN-1080 | B20: GWP.C01.01.01.06 | C20: L6 | D20: GWP-L3-010 | E20: GWP-GEN-1020 | F20: Mobilise cranes, excavators & batching equipment | G20: Task | H20: GEN | I20: Contractor Site Engineer | J20: 1 | K20: LS | L20: 6 | M20: GWP-GEN-1040 FS | N20: =IF($L20=0,O16,WORKDAY.INTL(O16,1,11)) -> 46673 | O20: =IF(L20=0,N20,WORKDAY.INTL(N20,L20-1,11)) -> 46679 | P20: Y | T20: =IF(ISNUMBER(R20),"Completed",IF(ISNUMBER(Q20),"In Progress","Not Started")) -> Not Started
A21: GWP-GEN-1090 | B21: GWP.C01.01.02 | C21: L5 | D21: GWP-L3-010 | E21: GWP-GEN-1010 | F21: Quality & HSE Setup | G21: Summary | H21: GEN | I21: Contractor Site Engineer | L21: =NETWORKDAYS.INTL(N21,O21,11) -> 11 | N21: =MIN(N22:N25) -> 46666 | O21: =MAX(O22:O25) -> 46678 | P21: N | Q21: =IF(COUNT(Q22:Q25)=0,"",MIN(Q22:Q25)) | R21: =IF(COUNTIFS(P22:P25,"Y")=COUNTIFS(P22:P25,"Y",R22:R25,">0"),MAX(R22:R25),"") | S21: =IFERROR(SUMPRODUCT((P22:P25="Y")*L22:L25*S22:S25)/SUMIFS(L22:L25,P22:P25,"Y"),0) -> 0 | T21: =IF(ISNUMBER(R21),"Completed",IF(ISNUMBER(Q21),"In Progress","Not Started")) -> Not Started
A22: GWP-HSE-1010 | B22: GWP.C01.01.02.01 | C22: L6 | D22: GWP-L3-010 | E22: GWP-GEN-1090 | F22: HSE plan approval & worker induction | G22: Task | H22: HSE | I22: Contractor HSE Officer | J22: 1 | K22: LS | L22: 5 | M22: GWP-GEN-1040 FS | N22: =IF($L22=0,O16,WORKDAY.INTL(O16,1,11)) -> 46673 | O22: =IF(L22=0,N22,WORKDAY.INTL(N22,L22-1,11)) -> 46678 | P22: Y | T22: =IF(ISNUMBER(R22),"Completed",IF(ISNUMBER(Q22),"In Progress","Not Started")) -> Not Started
A23: GWP-QAQC-1010 | B23: GWP.C01.01.02.02 | C23: L6 | D23: GWP-L3-010 | E23: GWP-GEN-1090 | F23: Approval of QAP / Inspection & Test Plans | G23: Task | H23: QAQC | I23: Contractor QA/QC Engineer | J23: 1 | K23: LS | L23: 8 | M23: GWP-GEN-1030 FS | N23: =IF($L23=0,O15,WORKDAY.INTL(O15,1,11)) -> 46666 | O23: =IF(L23=0,N23,WORKDAY.INTL(N23,L23-1,11)) -> 46674 | P23: Y | T23: =IF(ISNUMBER(R23),"Completed",IF(ISNUMBER(Q23),"In Progress","Not Started")) -> Not Started
A24: GWP-GEN-1100 | B24: GWP.C01.01.02.03 | C24: L6 | D24: GWP-L3-010 | E24: GWP-GEN-1090 | F24: Establish survey control points & benchmarks | G24: Task | H24: GEN | I24: Contractor Site Engineer | J24: 12 | K24: Nos | L24: 4 | M24: GWP-GEN-1030 FS | N24: =IF($L24=0,O15,WORKDAY.INTL(O15,1,11)) -> 46666 | O24: =IF(L24=0,N24,WORKDAY.INTL(N24,L24-1,11)) -> 46669 | P24: Y | T24: =IF(ISNUMBER(R24),"Completed",IF(ISNUMBER(Q24),"In Progress","Not Started")) -> Not Started
A25: GWP-QAQC-1020 | B25: GWP.C01.01.02.04 | C25: L6 | D25: GWP-L3-010 | E25: GWP-GEN-1090 | F25: Set up site material testing lab | G25: Task | H25: QAQC | I25: Contractor QA/QC Engineer | J25: 1 | K25: LS | L25: 5 | M25: GWP-GEN-1040 FS | N25: =IF($L25=0,O16,WORKDAY.INTL(O16,1,11)) -> 46673 | O25: =IF(L25=0,N25,WORKDAY.INTL(N25,L25-1,11)) -> 46678 | P25: Y | T25: =IF(ISNUMBER(R25),"Completed",IF(ISNUMBER(Q25),"In Progress","Not Started")) -> Not Started
A26: GWP-CIV-1010 | B26: GWP.C02.01 | C26: L4 | D26: GWP-L3-020 | E26: GWP-L3-020 | F26: Earthwork & Site Grading | G26: Summary | H26: CIV | I26: Civil Supervisor | L26: =NETWORKDAYS.INTL(N26,O26,11) -> 56 | N26: =MIN(N27:N36) -> 46680 | O26: =MAX(O27:O36) -> 46744 | P26: N | Q26: =IF(COUNT(Q27:Q36)=0,"",MIN(Q27:Q36)) | R26: =IF(COUNTIFS(P27:P36,"Y")=COUNTIFS(P27:P36,"Y",R27:R36,">0"),MAX(R27:R36),"") | S26: =IFERROR(SUMPRODUCT((P27:P36="Y")*L27:L36*S27:S36)/SUMIFS(L27:L36,P27:P36,"Y"),0) -> 0 | T26: =IF(ISNUMBER(R26),"Completed",IF(ISNUMBER(Q26),"In Progress","Not Started")) -> Not Started
A27: GWP-CIV-1020 | B27: GWP.C02.01.01 | C27: L5 | D27: GWP-L3-020 | E27: GWP-CIV-1010 | F27: Clearing & Grading | G27: Summary | H27: CIV | I27: Civil Supervisor | L27: =NETWORKDAYS.INTL(N27,O27,11) -> 25 | N27: =MIN(N28:N30) -> 46680 | O27: =MAX(O28:O30) -> 46708 | P27: N | Q27: =IF(COUNT(Q28:Q30)=0,"",MIN(Q28:Q30)) | R27: =IF(COUNTIFS(P28:P30,"Y")=COUNTIFS(P28:P30,"Y",R28:R30,">0"),MAX(R28:R30),"") | S27: =IFERROR(SUMPRODUCT((P28:P30="Y")*L28:L30*S28:S30)/SUMIFS(L28:L30,P28:P30,"Y"),0) -> 0 | T27: =IF(ISNUMBER(R27),"Completed",IF(ISNUMBER(Q27),"In Progress","Not Started")) -> Not Started
A28: GWP-CIV-1030 | B28: GWP.C02.01.01.01 | C28: L6 | D28: GWP-L3-020 | E28: GWP-CIV-1020 | F28: Clear & grub site vegetation and debris | G28: Task | H28: CIV | I28: Civil Supervisor | J28: 25000 | K28: m2 | L28: 6 | M28: GWP-GEN-1100 FS; GWP-GEN-1080 FS | N28: =MAX(IF($L28=0,O24,WORKDAY.INTL(O24,1,11)),IF($L28=0,O20,WORKDAY.INTL(O20,1,11))) -> 46680 | O28: =IF(L28=0,N28,WORKDAY.INTL(N28,L28-1,11)) -> 46686 | P28: Y | T28: =IF(ISNUMBER(R28),"Completed",IF(ISNUMBER(Q28),"In Progress","Not Started")) -> Not Started
A29: GWP-CIV-1040 | B29: GWP.C02.01.01.02 | C29: L6 | D29: GWP-L3-020 | E29: GWP-CIV-1020 | F29: Cut & fill to formation level | G29: Task | H29: CIV | I29: Civil Supervisor | J29: 18000 | K29: m3 | L29: 14 | M29: GWP-CIV-1030 FS | N29: =IF($L29=0,O28,WORKDAY.INTL(O28,1,11)) -> 46687 | O29: =IF(L29=0,N29,WORKDAY.INTL(N29,L29-1,11)) -> 46702 | P29: Y | T29: =IF(ISNUMBER(R29),"Completed",IF(ISNUMBER(Q29),"In Progress","Not Started")) -> Not Started
A30: GWP-CIV-1050 | B30: GWP.C02.01.01.03 | C30: L6 | D30: GWP-L3-020 | E30: GWP-CIV-1020 | F30: Compaction & field density tests on filled area | G30: Task | H30: CIV | I30: Civil Supervisor | J30: 25000 | K30: m2 | L30: 5 | M30: GWP-CIV-1040 FS | N30: =IF($L30=0,O29,WORKDAY.INTL(O29,1,11)) -> 46703 | O30: =IF(L30=0,N30,WORKDAY.INTL(N30,L30-1,11)) -> 46708 | P30: Y | T30: =IF(ISNUMBER(R30),"Completed",IF(ISNUMBER(Q30),"In Progress","Not Started")) -> Not Started
A31: GWP-CIV-1060 | B31: GWP.C02.01.02 | C31: L5 | D31: GWP-L3-020 | E31: GWP-CIV-1010 | F31: Boundary Wall & Main Gate | G31: Summary | H31: CIV | I31: Civil Supervisor | L31: =NETWORKDAYS.INTL(N31,O31,11) -> 50 | N31: =MIN(N32:N36) -> 46687 | O31: =MAX(O32:O36) -> 46744 | P31: N | Q31: =IF(COUNT(Q32:Q36)=0,"",MIN(Q32:Q36)) | R31: =IF(COUNTIFS(P32:P36,"Y")=COUNTIFS(P32:P36,"Y",R32:R36,">0"),MAX(R32:R36),"") | S31: =IFERROR(SUMPRODUCT((P32:P36="Y")*L32:L36*S32:S36)/SUMIFS(L32:L36,P32:P36,"Y"),0) -> 0 | T31: =IF(ISNUMBER(R31),"Completed",IF(ISNUMBER(Q31),"In Progress","Not Started")) -> Not Started
A32: GWP-CIV-1070 | B32: GWP.C02.01.02.01 | C32: L6 | D32: GWP-L3-020 | E32: GWP-CIV-1060 | F32: Excavate boundary wall foundation trench | G32: Task | H32: CIV | I32: Civil Supervisor | J32: 1200 | K32: RM | L32: 8 | M32: GWP-CIV-1030 FS | N32: =IF($L32=0,O28,WORKDAY.INTL(O28,1,11)) -> 46687 | O32: =IF(L32=0,N32,WORKDAY.INTL(N32,L32-1,11)) -> 46695 | P32: Y | T32: =IF(ISNUMBER(R32),"Completed",IF(ISNUMBER(Q32),"In Progress","Not Started")) -> Not Started
A33: GWP-CIV-1080 | B33: GWP.C02.01.02.02 | C33: L6 | D33: GWP-L3-020 | E33: GWP-CIV-1060 | F33: Lay PCC and footing for boundary wall | G33: Task | H33: CIV | I33: Civil Supervisor | J33: 1200 | K33: RM | L33: 10 | M33: GWP-CIV-1070 FS | N33: =IF($L33=0,O32,WORKDAY.INTL(O32,1,11)) -> 46696 | O33: =IF(L33=0,N33,WORKDAY.INTL(N33,L33-1,11)) -> 46707 | P33: Y | T33: =IF(ISNUMBER(R33),"Completed",IF(ISNUMBER(Q33),"In Progress","Not Started")) -> Not Started
A34: GWP-CIV-1090 | B34: GWP.C02.01.02.03 | C34: L6 | D34: GWP-L3-020 | E34: GWP-CIV-1060 | F34: Brick masonry for boundary wall | G34: Task | H34: CIV | I34: Civil Supervisor | J34: 1200 | K34: RM | L34: 20 | M34: GWP-CIV-1080 FS | N34: =IF($L34=0,O33,WORKDAY.INTL(O33,1,11)) -> 46708 | O34: =IF(L34=0,N34,WORKDAY.INTL(N34,L34-1,11)) -> 46730 | P34: Y | T34: =IF(ISNUMBER(R34),"Completed",IF(ISNUMBER(Q34),"In Progress","Not Started")) -> Not Started
A35: GWP-CIV-1100 | B35: GWP.C02.01.02.04 | C35: L6 | D35: GWP-L3-020 | E35: GWP-CIV-1060 | F35: Plaster & paint boundary wall | G35: Task | H35: CIV | I35: Civil Supervisor | J35: 1200 | K35: RM | L35: 12 | M35: GWP-CIV-1090 FS | N35: =IF($L35=0,O34,WORKDAY.INTL(O34,1,11)) -> 46731 | O35: =IF(L35=0,N35,WORKDAY.INTL(N35,L35-1,11)) -> 46744 | P35: Y | T35: =IF(ISNUMBER(R35),"Completed",IF(ISNUMBER(Q35),"In Progress","Not Started")) -> Not Started
A36: GWP-CIV-1110 | B36: GWP.C02.01.02.05 | C36: L6 | D36: GWP-L3-020 | E36: GWP-CIV-1060 | F36: Install main gate & security cabin | G36: Task | H36: CIV | I36: Civil Supervisor | J36: 1 | K36: LS | L36: 6 | M36: GWP-CIV-1090 FS | N36: =IF($L36=0,O34,WORKDAY.INTL(O34,1,11)) -> 46731 | O36: =IF(L36=0,N36,WORKDAY.INTL(N36,L36-1,11)) -> 46737 | P36: Y | T36: =IF(ISNUMBER(R36),"Completed",IF(ISNUMBER(Q36),"In Progress","Not Started")) -> Not Started
A37: GWP-CIV-1120 | B37: GWP.C02.02 | C37: L4 | D37: GWP-L3-020 | E37: GWP-L3-020 | F37: Roads & Drainage | G37: Summary | H37: CIV | I37: Civil Supervisor | L37: =NETWORKDAYS.INTL(N37,O37,11) -> 141 | N37: =MIN(N38:N47) -> 46709 | O37: =MAX(O38:O47) -> 46872 | P37: N | Q37: =IF(COUNT(Q38:Q47)=0,"",MIN(Q38:Q47)) | R37: =IF(COUNTIFS(P38:P47,"Y")=COUNTIFS(P38:P47,"Y",R38:R47,">0"),MAX(R38:R47),"") | S37: =IFERROR(SUMPRODUCT((P38:P47="Y")*L38:L47*S38:S47)/SUMIFS(L38:L47,P38:P47,"Y"),0) -> 0 | T37: =IF(ISNUMBER(R37),"Completed",IF(ISNUMBER(Q37),"In Progress","Not Started")) -> Not Started
A38: GWP-CIV-1130 | B38: GWP.C02.02.01 | C38: L5 | D38: GWP-L3-020 | E38: GWP-CIV-1120 | F38: Storm Water Drainage | G38: Summary | H38: CIV | I38: Civil Supervisor | L38: =NETWORKDAYS.INTL(N38,O38,11) -> 38 | N38: =MIN(N39:N42) -> 46709 | O38: =MAX(O39:O42) -> 46752 | P38: N | Q38: =IF(COUNT(Q39:Q42)=0,"",MIN(Q39:Q42)) | R38: =IF(COUNTIFS(P39:P42,"Y")=COUNTIFS(P39:P42,"Y",R39:R42,">0"),MAX(R39:R42),"") | S38: =IFERROR(SUMPRODUCT((P39:P42="Y")*L39:L42*S39:S42)/SUMIFS(L39:L42,P39:P42,"Y"),0) -> 0 | T38: =IF(ISNUMBER(R38),"Completed",IF(ISNUMBER(Q38),"In Progress","Not Started")) -> Not Started
A39: GWP-CIV-1140 | B39: GWP.C02.02.01.01 | C39: L6 | D39: GWP-L3-020 | E39: GWP-CIV-1130 | F39: Excavate storm drain trenches | G39: Task | H39: CIV | I39: Civil Supervisor | J39: 900 | K39: RM | L39: 10 | M39: GWP-CIV-1050 FS | N39: =IF($L39=0,O30,WORKDAY.INTL(O30,1,11)) -> 46709 | O39: =IF(L39=0,N39,WORKDAY.INTL(N39,L39-1,11)) -> 46720 | P39: Y | T39: =IF(ISNUMBER(R39),"Completed",IF(ISNUMBER(Q39),"In Progress","Not Started")) -> Not Started
A40: GWP-CIV-1150 | B40: GWP.C02.02.01.02 | C40: L6 | D40: GWP-L3-020 | E40: GWP-CIV-1130 | F40: PCC bed for drains | G40: Task | H40: CIV | I40: Civil Supervisor | J40: 900 | K40: RM | L40: 6 | M40: GWP-CIV-1140 FS | N40: =IF($L40=0,O39,WORKDAY.INTL(O39,1,11)) -> 46721 | O40: =IF(L40=0,N40,WORKDAY.INTL(N40,L40-1,11)) -> 46727 | P40: Y | T40: =IF(ISNUMBER(R40),"Completed",IF(ISNUMBER(Q40),"In Progress","Not Started")) -> Not Started
A41: GWP-CIV-1160 | B41: GWP.C02.02.01.03 | C41: L6 | D41: GWP-L3-020 | E41: GWP-CIV-1130 | F41: Construct drain side walls (masonry/RCC) | G41: Task | H41: CIV | I41: Civil Supervisor | J41: 900 | K41: RM | L41: 16 | M41: GWP-CIV-1150 FS | N41: =IF($L41=0,O40,WORKDAY.INTL(O40,1,11)) -> 46728 | O41: =IF(L41=0,N41,WORKDAY.INTL(N41,L41-1,11)) -> 46745 | P41: Y | T41: =IF(ISNUMBER(R41),"Completed",IF(ISNUMBER(Q41),"In Progress","Not Started")) -> Not Started
A42: GWP-CIV-1170 | B42: GWP.C02.02.01.04 | C42: L6 | D42: GWP-L3-020 | E42: GWP-CIV-1130 | F42: Fix drain covers and gratings | G42: Task | H42: CIV | I42: Civil Supervisor | J42: 900 | K42: RM | L42: 6 | M42: GWP-CIV-1160 FS | N42: =IF($L42=0,O41,WORKDAY.INTL(O41,1,11)) -> 46746 | O42: =IF(L42=0,N42,WORKDAY.INTL(N42,L42-1,11)) -> 46752 | P42: Y | T42: =IF(ISNUMBER(R42),"Completed",IF(ISNUMBER(Q42),"In Progress","Not Started")) -> Not Started
...

Sheet L3 Reference
A1: Level 3 Activities Assigned to the Construction Contractor (Consultant P6 schedule)
A2: Dates, counts and progress are calculated from the L4-L6 Schedule sheet. In the full project these L3 nodes sit inside the consultant's P6 L3 schedule.
A4: L3 Activity ID | B4: WBS | C4: L3 Activity Name | D4: Scope Summary | E4: Planned Start | F4: Planned Finish | G4: Duration (wd) | H4: # L4 | I4: # L5 | J4: # L6 tasks | K4: Actual Start | L4: Actual Finish | M4: % Complete | N4: Status
A5: GWP-L3-010 | B5: GWP.C01 | C5: Site Mobilisation & Temporary Facilities | D5: Site handover, temporary facilities, HSE/QA setup, survey control | E5: =_xlfn.MINIFS('L4-L6 Schedule'!$N$6:$N$220,'L4-L6 Schedule'!$D$6:$D$220,$A5) -> 46664 | F5: =_xlfn.MAXIFS('L4-L6 Schedule'!$O$6:$O$220,'L4-L6 Schedule'!$D$6:$D$220,$A5) -> 46679 | G5: =NETWORKDAYS.INTL(E5,F5,11) -> 14 | H5: =COUNTIFS('L4-L6 Schedule'!$D$6:$D$220,$A5,'L4-L6 Schedule'!$C$6:$C$220,"L4") -> 1 | I5: =COUNTIFS('L4-L6 Schedule'!$D$6:$D$220,$A5,'L4-L6 Schedule'!$C$6:$C$220,"L5") -> 2 | J5: =COUNTIFS('L4-L6 Schedule'!$D$6:$D$220,$A5,'L4-L6 Schedule'!$C$6:$C$220,"L6") -> 10 | K5: =IF(COUNTIFS('L4-L6 Schedule'!$D$6:$D$220,$A5,'L4-L6 Schedule'!$Q$6:$Q$220,">0")=0,"",_xlfn.MINIFS('L4-L6 Schedule'!$Q$6:$Q$220,'L4-L6 Schedule'!$D$6:$D$220,$A5)) | L5: =IF(COUNTIFS('L4-L6 Schedule'!$D$6:$D$220,$A5,'L4-L6 Schedule'!$P$6:$P$220,"Y")=COUNTIFS('L4-L6 Schedule'!$D$6:$D$220,$A5,'L4-L6 Schedule'!$P$6:$P$220,"Y",'L4-L6 Schedule'!$R$6:$R$220,">0"),_xlfn.MAXIFS('L4-L6 Schedule'!$R$6:$R$220,'L4-L6 Schedule'!$D$6:$D$220,$A5),"") | M5: =IFERROR(SUMPRODUCT(('L4-L6 Schedule'!$D$6:$D$220=$A5)*('L4-L6 Schedule'!$P$6:$P$220="Y")*'L4-L6 Schedule'!$L$6:$L$220*'L4-L6 Schedule'!$S$6:$S$220)/SUMIFS('L4-L6 Schedule'!$L$6:$L$220,'L4-L6 Schedule'!$D$6:$D$220,$A5,'L4-L6 Schedule'!$P$6:$P$220,"Y"),0) -> 0 | N5: =IF(ISNUMBER(L5),"Completed",IF(ISNUMBER(K5),"In Progress","Not Started")) -> Not Started
A6: GWP-L3-020 | B6: GWP.C02 | C6: Site Development & Enabling Works | D6: Grading, boundary wall, storm drains, internal roads | E6: =_xlfn.MINIFS('L4-L6 Schedule'!$N$6:$N$220,'L4-L6 Schedule'!$D$6:$D$220,$A6) -> 46680 | F6: =_xlfn.MAXIFS('L4-L6 Schedule'!$O$6:$O$220,'L4-L6 Schedule'!$D$6:$D$220,$A6) -> 46872 | G6: =NETWORKDAYS.INTL(E6,F6,11) -> 166 | H6: =COUNTIFS('L4-L6 Schedule'!$D$6:$D$220,$A6,'L4-L6 Schedule'!$C$6:$C$220,"L4") -> 2 | I6: =COUNTIFS('L4-L6 Schedule'!$D$6:$D$220,$A6,'L4-L6 Schedule'!$C$6:$C$220,"L5") -> 4 | J6: =COUNTIFS('L4-L6 Schedule'!$D$6:$D$220,$A6,'L4-L6 Schedule'!$C$6:$C$220,"L6") -> 16 | K6: =IF(COUNTIFS('L4-L6 Schedule'!$D$6:$D$220,$A6,'L4-L6 Schedule'!$Q$6:$Q$220,">0")=0,"",_xlfn.MINIFS('L4-L6 Schedule'!$Q$6:$Q$220,'L4-L6 Schedule'!$D$6:$D$220,$A6)) | L6: =IF(COUNTIFS('L4-L6 Schedule'!$D$6:$D$220,$A6,'L4-L6 Schedule'!$P$6:$P$220,"Y")=COUNTIFS('L4-L6 Schedule'!$D$6:$D$220,$A6,'L4-L6 Schedule'!$P$6:$P$220,"Y",'L4-L6 Schedule'!$R$6:$R$220,">0"),_xlfn.MAXIFS('L4-L6 Schedule'!$R$6:$R$220,'L4-L6 Schedule'!$D$6:$D$220,$A6),"") | M6: =IFERROR(SUMPRODUCT(('L4-L6 Schedule'!$D$6:$D$220=$A6)*('L4-L6 Schedule'!$P$6:$P$220="Y")*'L4-L6 Schedule'!$L$6:$L$220*'L4-L6 Schedule'!$S$6:$S$220)/SUMIFS('L4-L6 Schedule'!$L$6:$L$220,'L4-L6 Schedule'!$D$6:$D$220,$A6,'L4-L6 Schedule'!$P$6:$P$220,"Y"),0) -> 0 | N6: =IF(ISNUMBER(L6),"Completed",IF(ISNUMBER(K6),"In Progress","Not Started")) -> Not Started
A7: GWP-L3-030 | B7: GWP.C03 | C7: Civil Works - Process Buildings | D7: Tipping/receiving hall (Bldg B) and segregation & processing building (Bldg C): foundations, RCC, floors | E7: =_xlfn.MINIFS('L4-L6 Schedule'!$N$6:$N$220,'L4-L6 Schedule'!$D$6:$D$220,$A7) -> 46709 | F7: =_xlfn.MAXIFS('L4-L6 Schedule'!$O$6:$O$220,'L4-L6 Schedule'!$D$6:$D$220,$A7) -> 46790 | G7: =NETWORKDAYS.INTL(E7,F7,11) -> 70 | H7: =COUNTIFS('L4-L6 Schedule'!$D$6:$D$220,$A7,'L4-L6 Schedule'!$C$6:$C$220,"L4") -> 2 | I7: =COUNTIFS('L4-L6 Schedule'!$D$6:$D$220,$A7,'L4-L6 Schedule'!$C$6:$C$220,"L5") -> 6 | J7: =COUNTIFS('L4-L6 Schedule'!$D$6:$D$220,$A7,'L4-L6 Schedule'!$C$6:$C$220,"L6") -> 28 | K7: =IF(COUNTIFS('L4-L6 Schedule'!$D$6:$D$220,$A7,'L4-L6 Schedule'!$Q$6:$Q$220,">0")=0,"",_xlfn.MINIFS('L4-L6 Schedule'!$Q$6:$Q$220,'L4-L6 Schedule'!$D$6:$D$220,$A7)) | L7: =IF(COUNTIFS('L4-L6 Schedule'!$D$6:$D$220,$A7,'L4-L6 Schedule'!$P$6:$P$220,"Y")=COUNTIFS('L4-L6 Schedule'!$D$6:$D$220,$A7,'L4-L6 Schedule'!$P$6:$P$220,"Y",'L4-L6 Schedule'!$R$6:$R$220,">0"),_xlfn.MAXIFS('L4-L6 Schedule'!$R$6:$R$220,'L4-L6 Schedule'!$D$6:$D$220,$A7),"") | M7: =IFERROR(SUMPRODUCT(('L4-L6 Schedule'!$D$6:$D$220=$A7)*('L4-L6 Schedule'!$P$6:$P$220="Y")*'L4-L6 Schedule'!$L$6:$L$220*'L4-L6 Schedule'!$S$6:$S$220)/SUMIFS('L4-L6 Schedule'!$L$6:$L$220,'L4-L6 Schedule'!$D$6:$D$220,$A7,'L4-L6 Schedule'!$P$6:$P$220,"Y"),0) -> 0 | N7: =IF(ISNUMBER(L7),"Completed",IF(ISNUMBER(K7),"In Progress","Not Started")) -> Not Started
A8: GWP-L3-040 | B8: GWP.C04 | C8: Civil Works - Composting Yard, RDF Shed & Leachate Tanks | D8: Compost platform, RDF shed foundation/floor, leachate sump and tanks | E8: =_xlfn.MINIFS('L4-L6 Schedule'!$N$6:$N$220,'L4-L6 Schedule'!$D$6:$D$220,$A8) -> 46709 | F8: =_xlfn.MAXIFS('L4-L6 Schedule'!$O$6:$O$220,'L4-L6 Schedule'!$D$6:$D$220,$A8) -> 46752 | G8: =NETWORKDAYS.INTL(E8,F8,11) -> 38 | H8: =COUNTIFS('L4-L6 Schedule'!$D$6:$D$220,$A8,'L4-L6 Schedule'!$C$6:$C$220,"L4") -> 3 | I8: =COUNTIFS('L4-L6 Schedule'!$D$6:$D$220,$A8,'L4-L6 Schedule'!$C$6:$C$220,"L5") -> 3 | J8: =COUNTIFS('L4-L6 Schedule'!$D$6:$D$220,$A8,'L4-L6 Schedule'!$C$6:$C$220,"L6") -> 14 | K8: =IF(COUNTIFS('L4-L6 Schedule'!$D$6:$D$220,$A8,'L4-L6 Schedule'!$Q$6:$Q$220,">0")=0,"",_xlfn.MINIFS('L4-L6 Schedule'!$Q$6:$Q$220,'L4-L6 Schedule'!$D$6:$D$220,$A8)) | L8: =IF(COUNTIFS('L4-L6 Schedule'!$D$6:$D$220,$A8,'L4-L6 Schedule'!$P$6:$P$220,"Y")=COUNTIFS('L4-L6 Schedule'!$D$6:$D$220,$A8,'L4-L6 Schedule'!$P$6:$P$220,"Y",'L4-L6 Schedule'!$R$6:$R$220,">0"),_xlfn.MAXIFS('L4-L6 Schedule'!$R$6:$R$220,'L4-L6 Schedule'!$D$6:$D$220,$A8),"") | M8: =IFERROR(SUMPRODUCT(('L4-L6 Schedule'!$D$6:$D$220=$A8)*('L4-L6 Schedule'!$P$6:$P$220="Y")*'L4-L6 Schedule'!$L$6:$L$220*'L4-L6 Schedule'!$S$6:$S$220)/SUMIFS('L4-L6 Schedule'!$L$6:$L$220,'L4-L6 Schedule'!$D$6:$D$220,$A8,'L4-L6 Schedule'!$P$6:$P$220,"Y"),0) -> 0 | N8: =IF(ISNUMBER(L8),"Completed",IF(ISNUMBER(K8),"In Progress","Not Started")) -> Not Started
A9: GWP-L3-050 | B9: GWP.C05 | C9: Civil Works - Administration & Utility Buildings | D9: Admin/control building, substation & DG room, fire water tank, weighbridge foundation | E9: =_xlfn.MINIFS('L4-L6 Schedule'!$N$6:$N$220,'L4-L6 Schedule'!$D$6:$D$220,$A9) -> 46709 | F9: =_xlfn.MAXIFS('L4-L6 Schedule'!$O$6:$O$220,'L4-L6 Schedule'!$D$6:$D$220,$A9) -> 46794 | G9: =NETWORKDAYS.INTL(E9,F9,11) -> 74 | H9: =COUNTIFS('L4-L6 Schedule'!$D$6:$D$220,$A9,'L4-L6 Schedule'!$C$6:$C$220,"L4") -> 2 | I9: =COUNTIFS('L4-L6 Schedule'!$D$6:$D$220,$A9,'L4-L6 Schedule'!$C$6:$C$220,"L5") -> 3 | J9: =COUNTIFS('L4-L6 Schedule'!$D$6:$D$220,$A9,'L4-L6 Schedule'!$C$6:$C$220,"L6") -> 12 | K9: =IF(COUNTIFS('L4-L6 Schedule'!$D$6:$D$220,$A9,'L4-L6 Schedule'!$Q$6:$Q$220,">0")=0,"",_xlfn.MINIFS('L4-L6 Schedule'!$Q$6:$Q$220,'L4-L6 Schedule'!$D$6:$D$220,$A9)) | L9: =IF(COUNTIFS('L4-L6 Schedule'!$D$6:$D$220,$A9,'L4-L6 Schedule'!$P$6:$P$220,"Y")=COUNTIFS('L4-L6 Schedule'!$D$6:$D$220,$A9,'L4-L6 Schedule'!$P$6:$P$220,"Y",'L4-L6 Schedule'!$R$6:$R$220,">0"),_xlfn.MAXIFS('L4-L6 Schedule'!$R$6:$R$220,'L4-L6 Schedule'!$D$6:$D$220,$A9),"") | M9: =IFERROR(SUMPRODUCT(('L4-L6 Schedule'!$D$6:$D$220=$A9)*('L4-L6 Schedule'!$P$6:$P$220="Y")*'L4-L6 Schedule'!$L$6:$L$220*'L4-L6 Schedule'!$S$6:$S$220)/SUMIFS('L4-L6 Schedule'!$L$6:$L$220,'L4-L6 Schedule'!$D$6:$D$220,$A9,'L4-L6 Schedule'!$P$6:$P$220,"Y"),0) -> 0 | N9: =IF(ISNUMBER(L9),"Completed",IF(ISNUMBER(K9),"In Progress","Not Started")) -> Not Started
A10: GWP-L3-060 | B10: GWP.C06 | C10: Structural Steel Fabrication & Erection | D10: Trusses, columns, crane girders, platforms, roof sheeting, painting | E10: =_xlfn.MINIFS('L4-L6 Schedule'!$N$6:$N$220,'L4-L6 Schedule'!$D$6:$D$220,$A10) -> 46688 | F10: =_xlfn.MAXIFS('L4-L6 Schedule'!$O$6:$O$220,'L4-L6 Schedule'!$D$6:$D$220,$A10) -> 46815 | G10: =NETWORKDAYS.INTL(E10,F10,11) -> 110 | H10: =COUNTIFS('L4-L6 Schedule'!$D$6:$D$220,$A10,'L4-L6 Schedule'!$C$6:$C$220,"L4") -> 2 | I10: =COUNTIFS('L4-L6 Schedule'!$D$6:$D$220,$A10,'L4-L6 Schedule'!$C$6:$C$220,"L5") -> 5 | J10: =COUNTIFS('L4-L6 Schedule'!$D$6:$D$220,$A10,'L4-L6 Schedule'!$C$6:$C$220,"L6") -> 16 | K10: =IF(COUNTIFS('L4-L6 Schedule'!$D$6:$D$220,$A10,'L4-L6 Schedule'!$Q$6:$Q$220,">0")=0,"",_xlfn.MINIFS('L4-L6 Schedule'!$Q$6:$Q$220,'L4-L6 Schedule'!$D$6:$D$220,$A10)) | L10: =IF(COUNTIFS('L4-L6 Schedule'!$D$6:$D$220,$A10,'L4-L6 Schedule'!$P$6:$P$220,"Y")=COUNTIFS('L4-L6 Schedule'!$D$6:$D$220,$A10,'L4-L6 Schedule'!$P$6:$P$220,"Y",'L4-L6 Schedule'!$R$6:$R$220,">0"),_xlfn.MAXIFS('L4-L6 Schedule'!$R$6:$R$220,'L4-L6 Schedule'!$D$6:$D$220,$A10),"") | M10: =IFERROR(SUMPRODUCT(('L4-L6 Schedule'!$D$6:$D$220=$A10)*('L4-L6 Schedule'!$P$6:$P$220="Y")*'L4-L6 Schedule'!$L$6:$L$220*'L4-L6 Schedule'!$S$6:$S$220)/SUMIFS('L4-L6 Schedule'!$L$6:$L$220,'L4-L6 Schedule'!$D$6:$D$220,$A10,'L4-L6 Schedule'!$P$6:$P$220,"Y"),0) -> 0 | N10: =IF(ISNUMBER(L10),"Completed",IF(ISNUMBER(K10),"In Progress","Not Started")) -> Not Started
A11: GWP-L3-070 | B11: GWP.C07 | C11: Mechanical Equipment Erection | D11: Erection and alignment of supplier-furnished process equipment | E11: =_xlfn.MINIFS('L4-L6 Schedule'!$N$6:$N$220,'L4-L6 Schedule'!$D$6:$D$220,$A11) -> 46834 | F11: =_xlfn.MAXIFS('L4-L6 Schedule'!$O$6:$O$220,'L4-L6 Schedule'!$D$6:$D$220,$A11) -> 46858 | G11: =NETWORKDAYS.INTL(E11,F11,11) -> 22 | H11: =COUNTIFS('L4-L6 Schedule'!$D$6:$D$220,$A11,'L4-L6 Schedule'!$C$6:$C$220,"L4") -> 2 | I11: =COUNTIFS('L4-L6 Schedule'!$D$6:$D$220,$A11,'L4-L6 Schedule'!$C$6:$C$220,"L5") -> 4 | J11: =COUNTIFS('L4-L6 Schedule'!$D$6:$D$220,$A11,'L4-L6 Schedule'!$C$6:$C$220,"L6") -> 16 | K11: =IF(COUNTIFS('L4-L6 Schedule'!$D$6:$D$220,$A11,'L4-L6 Schedule'!$Q$6:$Q$220,">0")=0,"",_xlfn.MINIFS('L4-L6 Schedule'!$Q$6:$Q$220,'L4-L6 Schedule'!$D$6:$D$220,$A11)) | L11: =IF(COUNTIFS('L4-L6 Schedule'!$D$6:$D$220,$A11,'L4-L6 Schedule'!$P$6:$P$220,"Y")=COUNTIFS('L4-L6 Schedule'!$D$6:$D$220,$A11,'L4-L6 Schedule'!$P$6:$P$220,"Y",'L4-L6 Schedule'!$R$6:$R$220,">0"),_xlfn.MAXIFS('L4-L6 Schedule'!$R$6:$R$220,'L4-L6 Schedule'!$D$6:$D$220,$A11),"") | M11: =IFERROR(SUMPRODUCT(('L4-L6 Schedule'!$D$6:$D$220=$A11)*('L4-L6 Schedule'!$P$6:$P$220="Y")*'L4-L6 Schedule'!$L$6:$L$220*'L4-L6 Schedule'!$S$6:$S$220)/SUMIFS('L4-L6 Schedule'!$L$6:$L$220,'L4-L6 Schedule'!$D$6:$D$220,$A11,'L4-L6 Schedule'!$P$6:$P$220,"Y"),0) -> 0 | N11: =IF(ISNUMBER(L11),"Completed",IF(ISNUMBER(K11),"In Progress","Not Started")) -> Not Started
A12: GWP-L3-080 | B12: GWP.C08 | C12: Piping, Fire Water & ETP Mechanical Works | D12: Leachate/process piping, fire water network, ETP skids and pumps, plumbing | E12: =_xlfn.MINIFS('L4-L6 Schedule'!$N$6:$N$220,'L4-L6 Schedule'!$D$6:$D$220,$A12) -> 46688 | F12: =_xlfn.MAXIFS('L4-L6 Schedule'!$O$6:$O$220,'L4-L6 Schedule'!$D$6:$D$220,$A12) -> 46877 | G12: =NETWORKDAYS.INTL(E12,F12,11) -> 163 | H12: =COUNTIFS('L4-L6 Schedule'!$D$6:$D$220,$A12,'L4-L6 Schedule'!$C$6:$C$220,"L4") -> 2 | I12: =COUNTIFS('L4-L6 Schedule'!$D$6:$D$220,$A12,'L4-L6 Schedule'!$C$6:$C$220,"L5") -> 4 | J12: =COUNTIFS('L4-L6 Schedule'!$D$6:$D$220,$A12,'L4-L6 Schedule'!$C$6:$C$220,"L6") -> 10 | K12: =IF(COUNTIFS('L4-L6 Schedule'!$D$6:$D$220,$A12,'L4-L6 Schedule'!$Q$6:$Q$220,">0")=0,"",_xlfn.MINIFS('L4-L6 Schedule'!$Q$6:$Q$220,'L4-L6 Schedule'!$D$6:$D$220,$A12)) | L12: =IF(COUNTIFS('L4-L6 Schedule'!$D$6:$D$220,$A12,'L4-L6 Schedule'!$P$6:$P$220,"Y")=COUNTIFS('L4-L6 Schedule'!$D$6:$D$220,$A12,'L4-L6 Schedule'!$P$6:$P$220,"Y",'L4-L6 Schedule'!$R$6:$R$220,">0"),_xlfn.MAXIFS('L4-L6 Schedule'!$R$6:$R$220,'L4-L6 Schedule'!$D$6:$D$220,$A12),"") | M12: =IFERROR(SUMPRODUCT(('L4-L6 Schedule'!$D$6:$D$220=$A12)*('L4-L6 Schedule'!$P$6:$P$220="Y")*'L4-L6 Schedule'!$L$6:$L$220*'L4-L6 Schedule'!$S$6:$S$220)/SUMIFS('L4-L6 Schedule'!$L$6:$L$220,'L4-L6 Schedule'!$D$6:$D$220,$A12,'L4-L6 Schedule'!$P$6:$P$220,"Y"),0) -> 0 | N12: =IF(ISNUMBER(L12),"Completed",IF(ISNUMBER(K12),"In Progress","Not Started")) -> Not Started
A13: GWP-L3-090 | B13: GWP.C09 | C13: Electrical Installation | D13: Transformer, panels, DG, earthing, cable trays, cabling, lighting | E13: =_xlfn.MINIFS('L4-L6 Schedule'!$N$6:$N$220,'L4-L6 Schedule'!$D$6:$D$220,$A13) -> 46718 | F13: =_xlfn.MAXIFS('L4-L6 Schedule'!$O$6:$O$220,'L4-L6 Schedule'!$D$6:$D$220,$A13) -> 46923 | G13: =NETWORKDAYS.INTL(E13,F13,11) -> 176 | H13: =COUNTIFS('L4-L6 Schedule'!$D$6:$D$220,$A13,'L4-L6 Schedule'!$C$6:$C$220,"L4") -> 1 | I13: =COUNTIFS('L4-L6 Schedule'!$D$6:$D$220,$A13,'L4-L6 Schedule'!$C$6:$C$220,"L5") -> 3 | J13: =COUNTIFS('L4-L6 Schedule'!$D$6:$D$220,$A13,'L4-L6 Schedule'!$C$6:$C$220,"L6") -> 10 | K13: =IF(COUNTIFS('L4-L6 Schedule'!$D$6:$D$220,$A13,'L4-L6 Schedule'!$Q$6:$Q$220,">0")=0,"",_xlfn.MINIFS('L4-L6 Schedule'!$Q$6:$Q$220,'L4-L6 Schedule'!$D$6:$D$220,$A13)) | L13: =IF(COUNTIFS('L4-L6 Schedule'!$D$6:$D$220,$A13,'L4-L6 Schedule'!$P$6:$P$220,"Y")=COUNTIFS('L4-L6 Schedule'!$D$6:$D$220,$A13,'L4-L6 Schedule'!$P$6:$P$220,"Y",'L4-L6 Schedule'!$R$6:$R$220,">0"),_xlfn.MAXIFS('L4-L6 Schedule'!$R$6:$R$220,'L4-L6 Schedule'!$D$6:$D$220,$A13),"") | M13: =IFERROR(SUMPRODUCT(('L4-L6 Schedule'!$D$6:$D$220=$A13)*('L4-L6 Schedule'!$P$6:$P$220="Y")*'L4-L6 Schedule'!$L$6:$L$220*'L4-L6 Schedule'!$S$6:$S$220)/SUMIFS('L4-L6 Schedule'!$L$6:$L$220,'L4-L6 Schedule'!$D$6:$D$220,$A13,'L4-L6 Schedule'!$P$6:$P$220,"Y"),0) -> 0 | N13: =IF(ISNUMBER(L13),"Completed",IF(ISNUMBER(K13),"In Progress","Not Started")) -> Not Started
A14: GWP-L3-100 | B14: GWP.C10 | C14: Instrumentation & Automation Installation | D14: Field instruments, PLC/SCADA, weighbridge integration, CCTV & fire alarm | E14: =_xlfn.MINIFS('L4-L6 Schedule'!$N$6:$N$220,'L4-L6 Schedule'!$D$6:$D$220,$A14) -> 46805 | F14: =_xlfn.MAXIFS('L4-L6 Schedule'!$O$6:$O$220,'L4-L6 Schedule'!$D$6:$D$220,$A14) -> 46928 | G14: =NETWORKDAYS.INTL(E14,F14,11) -> 107 | H14: =COUNTIFS('L4-L6 Schedule'!$D$6:$D$220,$A14,'L4-L6 Schedule'!$C$6:$C$220,"L4") -> 1 | I14: =COUNTIFS('L4-L6 Schedule'!$D$6:$D$220,$A14,'L4-L6 Schedule'!$C$6:$C$220,"L5") -> 2 | J14: =COUNTIFS('L4-L6 Schedule'!$D$6:$D$220,$A14,'L4-L6 Schedule'!$C$6:$C$220,"L6") -> 6 | K14: =IF(COUNTIFS('L4-L6 Schedule'!$D$6:$D$220,$A14,'L4-L6 Schedule'!$Q$6:$Q$220,">0")=0,"",_xlfn.MINIFS('L4-L6 Schedule'!$Q$6:$Q$220,'L4-L6 Schedule'!$D$6:$D$220,$A14)) | L14: =IF(COUNTIFS('L4-L6 Schedule'!$D$6:$D$220,$A14,'L4-L6 Schedule'!$P$6:$P$220,"Y")=COUNTIFS('L4-L6 Schedule'!$D$6:$D$220,$A14,'L4-L6 Schedule'!$P$6:$P$220,"Y",'L4-L6 Schedule'!$R$6:$R$220,">0"),_xlfn.MAXIFS('L4-L6 Schedule'!$R$6:$R$220,'L4-L6 Schedule'!$D$6:$D$220,$A14),"") | M14: =IFERROR(SUMPRODUCT(('L4-L6 Schedule'!$D$6:$D$220=$A14)*('L4-L6 Schedule'!$P$6:$P$220="Y")*'L4-L6 Schedule'!$L$6:$L$220*'L4-L6 Schedule'!$S$6:$S$220)/SUMIFS('L4-L6 Schedule'!$L$6:$L$220,'L4-L6 Schedule'!$D$6:$D$220,$A14,'L4-L6 Schedule'!$P$6:$P$220,"Y"),0) -> 0 | N14: =IF(ISNUMBER(L14),"Completed",IF(ISNUMBER(K14),"In Progress","Not Started")) -> Not Started
A15: GWP-L3-110 | B15: GWP.C11 | C15: Construction Inspection, Testing & Mechanical Completion | D15: Hydrotests, megger, loop checks, cold runs, punch list, documentation, MC certificate | E15: =_xlfn.MINIFS('L4-L6 Schedule'!$N$6:$N$220,'L4-L6 Schedule'!$D$6:$D$220,$A15) -> 46816 | F15: =_xlfn.MAXIFS('L4-L6 Schedule'!$O$6:$O$220,'L4-L6 Schedule'!$D$6:$D$220,$A15) -> 46954 | G15: =NETWORKDAYS.INTL(E15,F15,11) -> 119 | H15: =COUNTIFS('L4-L6 Schedule'!$D$6:$D$220,$A15,'L4-L6 Schedule'!$C$6:$C$220,"L4") -> 1 | I15: =COUNTIFS('L4-L6 Schedule'!$D$6:$D$220,$A15,'L4-L6 Schedule'!$C$6:$C$220,"L5") -> 4 | J15: =COUNTIFS('L4-L6 Schedule'!$D$6:$D$220,$A15,'L4-L6 Schedule'!$C$6:$C$220,"L6") -> 11 | K15: =IF(COUNTIFS('L4-L6 Schedule'!$D$6:$D$220,$A15,'L4-L6 Schedule'!$Q$6:$Q$220,">0")=0,"",_xlfn.MINIFS('L4-L6 Schedule'!$Q$6:$Q$220,'L4-L6 Schedule'!$D$6:$D$220,$A15)) | L15: =IF(COUNTIFS('L4-L6 Schedule'!$D$6:$D$220,$A15,'L4-L6 Schedule'!$P$6:$P$220,"Y")=COUNTIFS('L4-L6 Schedule'!$D$6:$D$220,$A15,'L4-L6 Schedule'!$P$6:$P$220,"Y",'L4-L6 Schedule'!$R$6:$R$220,">0"),_xlfn.MAXIFS('L4-L6 Schedule'!$R$6:$R$220,'L4-L6 Schedule'!$D$6:$D$220,$A15),"") | M15: =IFERROR(SUMPRODUCT(('L4-L6 Schedule'!$D$6:$D$220=$A15)*('L4-L6 Schedule'!$P$6:$P$220="Y")*'L4-L6 Schedule'!$L$6:$L$220*'L4-L6 Schedule'!$S$6:$S$220)/SUMIFS('L4-L6 Schedule'!$L$6:$L$220,'L4-L6 Schedule'!$D$6:$D$220,$A15,'L4-L6 Schedule'!$P$6:$P$220,"Y"),0) -> 0 | N15: =IF(ISNUMBER(L15),"Completed",IF(ISNUMBER(K15),"In Progress","Not Started")) -> Not Started
C16: Package total | E16: =MIN(E5:E15) -> 46664 | F16: =MAX(F5:F15) -> 46954 | G16: =NETWORKDAYS.INTL(E16,F16,11) -> 250 | H16: =SUM(H5:H15) -> 19 | I16: =SUM(I5:I15) -> 40 | J16: =SUM(J5:J15) -> 149
A18: The last L3 node (Inspection, Testing & Mechanical Completion) ends with milestone "Mechanical Completion certificate (construction package)"; pre-commissioning and commissioning follow in other packages of the full L3 schedule.
