Workbook

Sheet README
A1: L3 Schedule (Synthetic Case)
A3: Purpose | B3: The consultant-level (L3) schedule for the case project, from investment approval to commissioning. It shows where the construction contractor's L4-L6 schedule sits in the whole project and gives the students the parent activities to which field updates roll up.
A4: Sheets | B4: L3 Schedule: activities, logic, dates and a monthly bar chart. Key Dates: milestones and consistency checks. This README.
A5: Phases | B5: 1 Project Initiation, Approval & Land; 2 Statutory Clearances & Inspections; 3 Utility Arrangements; 4 Design & Engineering; 5 Procurement; 6 Equipment Manufacture, Inspection & Delivery; 7 Construction (Contractor Package); 8 Completion, Pre-commissioning & Commissioning.
A6: Activity IDs | B6: Format GWP-L3-nnn. The 11 contractor L3 activities are GWP-L3-010 to GWP-L3-110 and match the L4-L6 Schedule workbook. Other packages use the hundreds digit: 2xx approval and land, 3xx statutory, 4xx utilities, 5xx design, 6xx procurement, 8xx supplier manufacture and delivery, 9xx completion and commissioning. Phase rows are GWP-PH-n.
A7: Link to L4-L6 workbook | B7: Contractor rows (green bars) carry fixed start and finish dates copied from the L4-L6 Schedule workbook. Site handover (GWP-L3-000) is driven by contract award and statutory logic and lands on the handover date that workbook assumes. The Key Dates sheet checks this.
A8: Back-solved durations | B8: Durations of GWP-L3-530, 640 and the equipment manufacture rows (810 to 860) were set so that structural steel IFC release, contract signing and supplier deliveries land on the dates assumed in the L4-L6 workbook. They are illustrative.
A9: Logic and calendar | B9: Finish-to-Start unless stated, with a few Start-to-Start lags. Six-day week (Sunday off), no holidays. Total float is not calculated. Durations and logic are synthetic assumptions for teaching, not from any real project.
A10: Legend | B10: Blue text: hardcoded input. Black: formula. Green text: link to another sheet. Yellow fill: key input to change. Bar colours: navy = phase, blue = L3 activity, green = contractor fixed window, red = milestone.
A11: Result | B11: Approval on 1 Jan 2027; site handover 4 Oct 2027; Mechanical Completion 20 Jul 2028; commissioning acceptance 22 Dec 2028, about one week before the 31 Dec 2028 target. See Key Dates.

Sheet L3 Schedule
A1: Level 3 Schedule: Urban Garbage Treatment Plant (100 TPD), Town XYZ, Company ABC - Investment Approval to Commissioning
A2: Synthetic teaching schedule in Primavera P6 style. Blue = input, black = formula. Contractor L3 windows (green) are fixed from the L4-L6 Schedule workbook. Six-day week (Sunday off).
A5: Activity ID | B5: WBS | C5: Level | D5: Activity Name | E5: Type | F5: Responsible | G5: Orig Duration (wd) | H5: Predecessors (FS unless stated) | I5: Planned Start | J5: Planned Finish | K5: 46388 | L5: =EDATE(K5,1) -> 46419 | M5: =EDATE(L5,1) -> 46447 | N5: =EDATE(M5,1) -> 46478 | O5: =EDATE(N5,1) -> 46508 | P5: =EDATE(O5,1) -> 46539 | Q5: =EDATE(P5,1) -> 46569 | R5: =EDATE(Q5,1) -> 46600 | S5: =EDATE(R5,1) -> 46631 | ... AH5: =EDATE(AG5,1) -> 47088
A6: GWP-PH-1 | B6: GWP.01 | C6: Phase | D6: Project Initiation, Approval & Land Acquisition | G6: =NETWORKDAYS.INTL(I6,J6,11) -> 106 | I6: =MIN(I7:I16) -> 46388 | J6: =MAX(J7:J16) -> 46511
A7: GWP-L3-200 | B7: GWP.01.01 | C7: L3 | D7: Investment approval by Company ABC Board | E7: Milestone | F7: Company ABC | G7: 0 | H7: Board decision date (input) | I7: 46388 | J7: =I7 -> 46388
A8: GWP-L3-210 | B8: GWP.01.02 | C8: L3 | D8: Appoint project management consultant (PMC) | E8: Task | F8: Company ABC | G8: 40 | H8: GWP-L3-200 FS | I8: =IF($G8=0,J7,WORKDAY.INTL(J7,1,11)) -> 46389 | J8: =IF(G8=0,I8,WORKDAY.INTL(I8,G8-1,11)) -> 46435
A9: GWP-L3-220 | B9: GWP.01.03 | C9: L3 | D9: Project organisation, budget & baseline schedule approval | E9: Task | F9: Company ABC | G9: 20 | H9: GWP-L3-210 FS | I9: =IF($G9=0,J8,WORKDAY.INTL(J8,1,11)) -> 46436 | J9: =IF(G9=0,I9,WORKDAY.INTL(I9,G9-1,11)) -> 46458
A10: GWP-L3-230 | B10: GWP.01.04 | C10: L3 | D10: Identify and finalise land parcel | E10: Task | F10: Company ABC | G10: 20 | H10: GWP-L3-200 FS | I10: =IF($G10=0,J7,WORKDAY.INTL(J7,1,11)) -> 46389 | J10: =IF(G10=0,I10,WORKDAY.INTL(I10,G10-1,11)) -> 46412
A11: GWP-L3-240 | B11: GWP.01.05 | C11: L3 | D11: Land title verification & due diligence | E11: Task | F11: Company ABC | G11: 15 | H11: GWP-L3-230 FS | I11: =IF($G11=0,J10,WORKDAY.INTL(J10,1,11)) -> 46413 | J11: =IF(G11=0,I11,WORKDAY.INTL(I11,G11-1,11)) -> 46429
A12: GWP-L3-250 | B12: GWP.01.06 | C12: L3 | D12: Land transfer / lease agreement with municipality | E12: Task | F12: Company ABC | G12: 25 | H12: GWP-L3-240 FS | I12: =IF($G12=0,J11,WORKDAY.INTL(J11,1,11)) -> 46430 | J12: =IF(G12=0,I12,WORKDAY.INTL(I12,G12-1,11)) -> 46458
A13: GWP-L3-260 | B13: GWP.01.07 | C13: L3 | D13: Land registration & mutation | E13: Task | F13: Company ABC | G13: 15 | H13: GWP-L3-250 FS | I13: =IF($G13=0,J12,WORKDAY.INTL(J12,1,11)) -> 46459 | J13: =IF(G13=0,I13,WORKDAY.INTL(I13,G13-1,11)) -> 46476
A14: GWP-L3-270 | B14: GWP.01.08 | C14: L3 | D14: Land possession & boundary demarcation | E14: Task | F14: Company ABC | G14: 5 | H14: GWP-L3-260 FS | I14: =IF($G14=0,J13,WORKDAY.INTL(J13,1,11)) -> 46477 | J14: =IF(G14=0,I14,WORKDAY.INTL(I14,G14-1,11)) -> 46482
A15: GWP-L3-275 | B15: GWP.01.09 | C15: L3 | D15: Topographic survey | E15: Task | F15: PMC / Consultant | G15: 10 | H15: GWP-L3-270 FS | I15: =IF($G15=0,J14,WORKDAY.INTL(J14,1,11)) -> 46483 | J15: =IF(G15=0,I15,WORKDAY.INTL(I15,G15-1,11)) -> 46493
A16: GWP-L3-280 | B16: GWP.01.10 | C16: L3 | D16: Geotechnical investigation & soil report | E16: Task | F16: PMC / Consultant | G16: 25 | H16: GWP-L3-270 FS | I16: =IF($G16=0,J14,WORKDAY.INTL(J14,1,11)) -> 46483 | J16: =IF(G16=0,I16,WORKDAY.INTL(I16,G16-1,11)) -> 46511
A17: GWP-PH-2 | B17: GWP.02 | C17: Phase | D17: Statutory Clearances & Inspections | G17: =NETWORKDAYS.INTL(I17,J17,11) -> 515 | I17: =MIN(I18:I28) -> 46389 | J17: =MAX(J18:J28) -> 46989
A18: GWP-L3-300 | B18: GWP.02.01 | C18: L3 | D18: Prepare statutory application documents (site details, process description) | E18: Task | F18: PMC / Consultant | G18: 30 | H18: GWP-L3-200 FS | I18: =IF($G18=0,J7,WORKDAY.INTL(J7,1,11)) -> 46389 | J18: =IF(G18=0,I18,WORKDAY.INTL(I18,G18-1,11)) -> 46423
A19: GWP-L3-310 | B19: GWP.02.02 | C19: L3 | D19: Land use / zoning permission (Town Planning) | E19: Task | F19: Company ABC | G19: 45 | H19: GWP-L3-250 FS; GWP-L3-300 FS | I19: =MAX(IF($G19=0,J12,WORKDAY.INTL(J12,1,11)),IF($G19=0,J18,WORKDAY.INTL(J18,1,11))) -> 46459 | J19: =IF(G19=0,I19,WORKDAY.INTL(I19,G19-1,11)) -> 46511
A20: GWP-L3-320 | B20: GWP.02.03 | C20: L3 | D20: Consent to Establish (State Pollution Control Board) | E20: Task | F20: Company ABC | G20: 60 | H20: GWP-L3-310 FS | I20: =IF($G20=0,J19,WORKDAY.INTL(J19,1,11)) -> 46512 | J20: =IF(G20=0,I20,WORKDAY.INTL(I20,G20-1,11)) -> 46581
A21: GWP-L3-330 | B21: GWP.02.04 | C21: L3 | D21: Building plan approval (Town Planning Authority) | E21: Task | F21: Company ABC | G21: 40 | H21: GWP-L3-510 FS | I21: =IF($G21=0,J41,WORKDAY.INTL(J41,1,11)) -> 46529 | J21: =IF(G21=0,I21,WORKDAY.INTL(I21,G21-1,11)) -> 46575
A22: GWP-L3-340 | B22: GWP.02.05 | C22: L3 | D22: Groundwater / borewell NOC | E22: Task | F22: Company ABC | G22: 30 | H22: GWP-L3-310 FS | I22: =IF($G22=0,J19,WORKDAY.INTL(J19,1,11)) -> 46512 | J22: =IF(G22=0,I22,WORKDAY.INTL(I22,G22-1,11)) -> 46546
A23: GWP-L3-350 | B23: GWP.02.06 | C23: L3 | D23: Electrical drawings approval & power sanction (Electrical Inspectorate) | E23: Task | F23: Company ABC | G23: 35 | H23: GWP-L3-550 FS | I23: =IF($G23=0,J45,WORKDAY.INTL(J45,1,11)) -> 46529 | J23: =IF(G23=0,I23,WORKDAY.INTL(I23,G23-1,11)) -> 46569
A24: GWP-L3-360 | B24: GWP.02.07 | C24: L3 | D24: Fire safety provisional NOC | E24: Task | F24: Company ABC | G24: 30 | H24: GWP-L3-330 FS | I24: =IF($G24=0,J21,WORKDAY.INTL(J21,1,11)) -> 46576 | J24: =IF(G24=0,I24,WORKDAY.INTL(I24,G24-1,11)) -> 46610
A25: GWP-L3-370 | B25: GWP.02.08 | C25: L3 | D25: Labour licence & BOCW registration for construction | E25: Task | F25: Contractor | G25: 10 | H25: GWP-L3-630 FS | I25: =IF($G25=0,J54,WORKDAY.INTL(J54,1,11)) -> 46646 | J25: =IF(G25=0,I25,WORKDAY.INTL(I25,G25-1,11)) -> 46657
A26: GWP-L3-380 | B26: GWP.02.09 | C26: L3 | D26: Consent to Operate application & inspection (SPCB) | E26: Task | F26: Company ABC | G26: 30 | H26: GWP-L3-900 FS | I26: =IF($G26=0,J90,WORKDAY.INTL(J90,1,11)) -> 46955 | J26: =IF(G26=0,I26,WORKDAY.INTL(I26,G26-1,11)) -> 46989
A27: GWP-L3-385 | B27: GWP.02.10 | C27: L3 | D27: Electrical Inspector approval for energisation | E27: Task | F27: Company ABC | G27: 25 | H27: GWP-L3-090 FS | I27: =IF($G27=0,J85,WORKDAY.INTL(J85,1,11)) -> 46924 | J27: =IF(G27=0,I27,WORKDAY.INTL(I27,G27-1,11)) -> 46952
A28: GWP-L3-390 | B28: GWP.02.11 | C28: L3 | D28: Final fire safety NOC (inspection) | E28: Task | F28: Company ABC | G28: 25 | H28: GWP-L3-080 FS | I28: =IF($G28=0,J84,WORKDAY.INTL(J84,1,11)) -> 46878 | J28: =IF(G28=0,I28,WORKDAY.INTL(I28,G28-1,11)) -> 46906
A29: GWP-PH-3 | B29: GWP.03 | C29: Phase | D29: Utility Arrangements | G29: =NETWORKDAYS.INTL(I29,J29,11) -> 160 | I29: =MIN(I30:I38) -> 46459 | J29: =MAX(J30:J38) -> 46645
A30: GWP-L3-400 | B30: GWP.03.01 | C30: L3 | D30: Power: load sanction application to DISCOM | E30: Task | F30: Company ABC | G30: 20 | H30: GWP-L3-250 FS | I30: =IF($G30=0,J12,WORKDAY.INTL(J12,1,11)) -> 46459 | J30: =IF(G30=0,I30,WORKDAY.INTL(I30,G30-1,11)) -> 46482
A31: GWP-L3-410 | B31: GWP.03.02 | C31: L3 | D31: Power: DISCOM estimate & payment | E31: Task | F31: Company ABC | G31: 20 | H31: GWP-L3-400 FS | I31: =IF($G31=0,J30,WORKDAY.INTL(J30,1,11)) -> 46483 | J31: =IF(G31=0,I31,WORKDAY.INTL(I31,G31-1,11)) -> 46505
A32: GWP-L3-420 | B32: GWP.03.03 | C32: L3 | D32: Power: 11 kV line, metering & HT connection by DISCOM | E32: Task | F32: DISCOM | G32: 100 | H32: GWP-L3-410 FS | I32: =IF($G32=0,J31,WORKDAY.INTL(J31,1,11)) -> 46506 | J32: =IF(G32=0,I32,WORKDAY.INTL(I32,G32-1,11)) -> 46622
A33: GWP-L3-430 | B33: GWP.03.04 | C33: L3 | D33: Water: source permission from municipal water board | E33: Task | F33: Company ABC | G33: 30 | H33: GWP-L3-250 FS | I33: =IF($G33=0,J12,WORKDAY.INTL(J12,1,11)) -> 46459 | J33: =IF(G33=0,I33,WORKDAY.INTL(I33,G33-1,11)) -> 46493
A34: GWP-L3-440 | B34: GWP.03.05 | C34: L3 | D34: Water: pipeline connection to site | E34: Task | F34: Municipality | G34: 45 | H34: GWP-L3-430 FS | I34: =IF($G34=0,J33,WORKDAY.INTL(J33,1,11)) -> 46494 | J34: =IF(G34=0,I34,WORKDAY.INTL(I34,G34-1,11)) -> 46546
A35: GWP-L3-450 | B35: GWP.03.06 | C35: L3 | D35: Approach road & site access improvement | E35: Task | F35: Municipality | G35: 40 | H35: GWP-L3-270 FS | I35: =IF($G35=0,J14,WORKDAY.INTL(J14,1,11)) -> 46483 | J35: =IF(G35=0,I35,WORKDAY.INTL(I35,G35-1,11)) -> 46528
A36: GWP-L3-460 | B36: GWP.03.07 | C36: L3 | D36: Feedstock supply agreement with municipality (waste quantity, tipping fee) | E36: Task | F36: Company ABC | G36: 60 | H36: GWP-L3-220 FS | I36: =IF($G36=0,J9,WORKDAY.INTL(J9,1,11)) -> 46459 | J36: =IF(G36=0,I36,WORKDAY.INTL(I36,G36-1,11)) -> 46528
A37: GWP-L3-470 | B37: GWP.03.08 | C37: L3 | D37: Treated water / storm discharge point permission | E37: Task | F37: Company ABC | G37: 25 | H37: GWP-L3-310 FS | I37: =IF($G37=0,J19,WORKDAY.INTL(J19,1,11)) -> 46512 | J37: =IF(G37=0,I37,WORKDAY.INTL(I37,G37-1,11)) -> 46540
A38: GWP-L3-480 | B38: GWP.03.09 | C38: L3 | D38: Telecom & internet connectivity for SCADA | E38: Task | F38: Company ABC | G38: 20 | H38: GWP-L3-420 FS | I38: =IF($G38=0,J32,WORKDAY.INTL(J32,1,11)) -> 46623 | J38: =IF(G38=0,I38,WORKDAY.INTL(I38,G38-1,11)) -> 46645
A39: GWP-PH-4 | B39: GWP.04 | C39: Phase | D39: Design & Engineering | G39: =NETWORKDAYS.INTL(I39,J39,11) -> 216 | I39: =MIN(I40:I49) -> 46436 | J39: =MAX(J40:J49) -> 46687
A40: GWP-L3-500 | B40: GWP.04.01 | C40: L3 | D40: Basic engineering: process flow, mass balance & P&IDs | E40: Task | F40: PMC / Consultant | G40: 40 | H40: GWP-L3-210 FS | I40: =IF($G40=0,J8,WORKDAY.INTL(J8,1,11)) -> 46436 | J40: =IF(G40=0,I40,WORKDAY.INTL(I40,G40-1,11)) -> 46482
A41: GWP-L3-510 | B41: GWP.04.02 | C41: L3 | D41: Plot plan & general arrangement of buildings | E41: Task | F41: PMC / Consultant | G41: 30 | H41: GWP-L3-500 FS; GWP-L3-275 FS | I41: =MAX(IF($G41=0,J40,WORKDAY.INTL(J40,1,11)),IF($G41=0,J15,WORKDAY.INTL(J15,1,11))) -> 46494 | J41: =IF(G41=0,I41,WORKDAY.INTL(I41,G41-1,11)) -> 46528
A42: GWP-L3-520 | B42: GWP.04.03 | C42: L3 | D42: Civil & structural design: foundations & RCC (IFC) | E42: Task | F42: PMC / Consultant | G42: 60 | H42: GWP-L3-510 FS; GWP-L3-280 FS | I42: =MAX(IF($G42=0,J41,WORKDAY.INTL(J41,1,11)),IF($G42=0,J16,WORKDAY.INTL(J16,1,11))) -> 46529 | J42: =IF(G42=0,I42,WORKDAY.INTL(I42,G42-1,11)) -> 46598
...

Sheet Key Dates
A1: Key Dates and Consistency Checks
A2: All dates are looked up from the L3 Schedule sheet.
A4: Milestone | B4: Activity ID | C4: Date | D4: Basis
A5: Investment approval | B5: GWP-L3-200 | C5: =INDEX('L3 Schedule'!$J$6:$J$97,MATCH(B5,'L3 Schedule'!$A$6:$A$97,0)) -> 46388 | D5: Finish
A6: Land possession achieved | B6: GWP-L3-270 | C6: =INDEX('L3 Schedule'!$J$6:$J$97,MATCH(B6,'L3 Schedule'!$A$6:$A$97,0)) -> 46482 | D6: Finish
A7: Consent to Establish granted | B7: GWP-L3-320 | C7: =INDEX('L3 Schedule'!$J$6:$J$97,MATCH(B7,'L3 Schedule'!$A$6:$A$97,0)) -> 46581 | D7: Finish
A8: Letter of Award to construction contractor | B8: GWP-L3-630 | C8: =INDEX('L3 Schedule'!$J$6:$J$97,MATCH(B8,'L3 Schedule'!$A$6:$A$97,0)) -> 46645 | D8: Finish
A9: Contract signed | B9: GWP-L3-640 | C9: =INDEX('L3 Schedule'!$J$6:$J$97,MATCH(B9,'L3 Schedule'!$A$6:$A$97,0)) -> 46662 | D9: Finish
A10: Site handover to contractor | B10: GWP-L3-000 | C10: =INDEX('L3 Schedule'!$I$6:$I$97,MATCH(B10,'L3 Schedule'!$A$6:$A$97,0)) -> 46664 | D10: Start
A11: Structural steel IFC drawings released | B11: GWP-L3-530 | C11: =INDEX('L3 Schedule'!$J$6:$J$97,MATCH(B11,'L3 Schedule'!$A$6:$A$97,0)) -> 46687 | D11: Finish
A12: Delivery at site: trommel, conveyors, feed hopper, weighbridge | B12: GWP-L3-815 | C12: =INDEX('L3 Schedule'!$J$6:$J$97,MATCH(B12,'L3 Schedule'!$A$6:$A$97,0)) -> 46833 | D12: Finish
A13: Delivery at site: shredder & baling press | B13: GWP-L3-825 | C13: =INDEX('L3 Schedule'!$J$6:$J$97,MATCH(B13,'L3 Schedule'!$A$6:$A$97,0)) -> 46844 | D13: Finish
A14: Delivery at site: composting equipment | B14: GWP-L3-835 | C14: =INDEX('L3 Schedule'!$J$6:$J$97,MATCH(B14,'L3 Schedule'!$A$6:$A$97,0)) -> 46839 | D14: Finish
A15: Delivery at site: ETP skid & pumps | B15: GWP-L3-845 | C15: =INDEX('L3 Schedule'!$J$6:$J$97,MATCH(B15,'L3 Schedule'!$A$6:$A$97,0)) -> 46844 | D15: Finish
A16: Delivery at site: transformer, panels, DG | B16: GWP-L3-855 | C16: =INDEX('L3 Schedule'!$J$6:$J$97,MATCH(B16,'L3 Schedule'!$A$6:$A$97,0)) -> 46868 | D16: Finish
A17: Delivery at site: PLC/SCADA & instruments | B17: GWP-L3-865 | C17: =INDEX('L3 Schedule'!$J$6:$J$97,MATCH(B17,'L3 Schedule'!$A$6:$A$97,0)) -> 46903 | D17: Finish
A18: Mechanical Completion | B18: GWP-L3-900 | C18: =INDEX('L3 Schedule'!$J$6:$J$97,MATCH(B18,'L3 Schedule'!$A$6:$A$97,0)) -> 46954 | D18: Finish
A19: Grid power charged | B19: GWP-L3-905 | C19: =INDEX('L3 Schedule'!$J$6:$J$97,MATCH(B19,'L3 Schedule'!$A$6:$A$97,0)) -> 46958 | D19: Finish
A20: Consent to Operate obtained | B20: GWP-L3-380 | C20: =INDEX('L3 Schedule'!$J$6:$J$97,MATCH(B20,'L3 Schedule'!$A$6:$A$97,0)) -> 46989 | D20: Finish
A21: Pre-commissioning complete | B21: GWP-L3-910 | C21: =INDEX('L3 Schedule'!$J$6:$J$97,MATCH(B21,'L3 Schedule'!$A$6:$A$97,0)) -> 46993 | D21: Finish
A22: Commissioning acceptance & handover | B22: GWP-L3-970 | C22: =INDEX('L3 Schedule'!$J$6:$J$97,MATCH(B22,'L3 Schedule'!$A$6:$A$97,0)) -> 47109 | D22: Finish
A24: Checks
A25: Handover date required by contractor L4-L6 schedule | C25: 46664
A26: Site handover date in this L3 schedule | C26: =C10 -> 46664
A27: Handover check | C27: =IF(C26<=C25,"OK - handover is on or before required date","LATE - contractor schedule cannot start") -> OK - handover is on or before required date
A28: Months from approval to commissioning acceptance | C28: =ROUND((C22-C5)/30.4375,1) -> 23.7
A29: Working days of float to 31-Dec-2028 target | C29: =NETWORKDAYS.INTL(C22,DATE(2028,12,31),11)-1 -> 7
A31: Handover required date is the "Site handover" input of the L4-L6 Schedule workbook (Assumptions sheet). Update both if you change it.
